2018-10-31 09:32:03,681 ERROR: Exception on /explore [GET] [in /home/nate/.local/lib/python3.6/site-packages/flask/app.py:1761]
Traceback (most recent call last):
  File "/home/nate/.local/lib/python3.6/site-packages/flask/app.py", line 2292, in wsgi_app
    response = self.full_dispatch_request()
  File "/home/nate/.local/lib/python3.6/site-packages/flask/app.py", line 1815, in full_dispatch_request
    rv = self.handle_user_exception(e)
  File "/home/nate/.local/lib/python3.6/site-packages/flask/app.py", line 1718, in handle_user_exception
    reraise(exc_type, exc_value, tb)
  File "/home/nate/.local/lib/python3.6/site-packages/flask/_compat.py", line 35, in reraise
    raise value
  File "/home/nate/.local/lib/python3.6/site-packages/flask/app.py", line 1813, in full_dispatch_request
    rv = self.dispatch_request()
  File "/home/nate/.local/lib/python3.6/site-packages/flask/app.py", line 1799, in dispatch_request
    return self.view_functions[rule.endpoint](**req.view_args)
  File "/home/nate/.local/lib/python3.6/site-packages/flask_login/utils.py", line 261, in decorated_view
    return func(*args, **kwargs)
  File "/home/nate/Documents/BadDoggy/Artemis/app/routes.py", line 91, in explore
    if User.email in app.config.ADMINS:
AttributeError: 'Config' object has no attribute 'ADMINS'
2018-10-31 09:35:58,769 ERROR: Exception on /explore [GET] [in /home/nate/.local/lib/python3.6/site-packages/flask/app.py:1761]
Traceback (most recent call last):
  File "/home/nate/.local/lib/python3.6/site-packages/flask/app.py", line 2292, in wsgi_app
    response = self.full_dispatch_request()
  File "/home/nate/.local/lib/python3.6/site-packages/flask/app.py", line 1815, in full_dispatch_request
    rv = self.handle_user_exception(e)
  File "/home/nate/.local/lib/python3.6/site-packages/flask/app.py", line 1718, in handle_user_exception
    reraise(exc_type, exc_value, tb)
  File "/home/nate/.local/lib/python3.6/site-packages/flask/_compat.py", line 35, in reraise
    raise value
  File "/home/nate/.local/lib/python3.6/site-packages/flask/app.py", line 1813, in full_dispatch_request
    rv = self.dispatch_request()
  File "/home/nate/.local/lib/python3.6/site-packages/flask/app.py", line 1799, in dispatch_request
    return self.view_functions[rule.endpoint](**req.view_args)
  File "/home/nate/.local/lib/python3.6/site-packages/flask_login/utils.py", line 261, in decorated_view
    return func(*args, **kwargs)
  File "/home/nate/Documents/BadDoggy/Artemis/app/routes.py", line 91, in explore
    if User.email in app.config.ADMINS:
AttributeError: 'Config' object has no attribute 'ADMINS'
2018-10-31 09:37:11,430 INFO: Artemis Startup [in /home/nate/Documents/BadDoggy/Artemis/app/__init__.py:50]
2018-10-31 09:37:15,942 ERROR: Exception on /explore [GET] [in /home/nate/.local/lib/python3.6/site-packages/flask/app.py:1761]
Traceback (most recent call last):
  File "/home/nate/.local/lib/python3.6/site-packages/flask/app.py", line 2292, in wsgi_app
    response = self.full_dispatch_request()
  File "/home/nate/.local/lib/python3.6/site-packages/flask/app.py", line 1815, in full_dispatch_request
    rv = self.handle_user_exception(e)
  File "/home/nate/.local/lib/python3.6/site-packages/flask/app.py", line 1718, in handle_user_exception
    reraise(exc_type, exc_value, tb)
  File "/home/nate/.local/lib/python3.6/site-packages/flask/_compat.py", line 35, in reraise
    raise value
  File "/home/nate/.local/lib/python3.6/site-packages/flask/app.py", line 1813, in full_dispatch_request
    rv = self.dispatch_request()
  File "/home/nate/.local/lib/python3.6/site-packages/flask/app.py", line 1799, in dispatch_request
    return self.view_functions[rule.endpoint](**req.view_args)
  File "/home/nate/.local/lib/python3.6/site-packages/flask_login/utils.py", line 261, in decorated_view
    return func(*args, **kwargs)
  File "/home/nate/Documents/BadDoggy/Artemis/app/routes.py", line 91, in explore
    if User.email in app.config.ADMINS:
AttributeError: 'Config' object has no attribute 'ADMINS'
2018-10-31 09:39:51,860 INFO: Artemis Startup [in /home/nate/Documents/BadDoggy/Artemis/app/__init__.py:50]
2018-10-31 09:39:54,337 ERROR: Exception on /explore [GET] [in /home/nate/.local/lib/python3.6/site-packages/flask/app.py:1761]
Traceback (most recent call last):
  File "/home/nate/.local/lib/python3.6/site-packages/flask/app.py", line 2292, in wsgi_app
    response = self.full_dispatch_request()
  File "/home/nate/.local/lib/python3.6/site-packages/flask/app.py", line 1815, in full_dispatch_request
    rv = self.handle_user_exception(e)
  File "/home/nate/.local/lib/python3.6/site-packages/flask/app.py", line 1718, in handle_user_exception
    reraise(exc_type, exc_value, tb)
  File "/home/nate/.local/lib/python3.6/site-packages/flask/_compat.py", line 35, in reraise
    raise value
  File "/home/nate/.local/lib/python3.6/site-packages/flask/app.py", line 1813, in full_dispatch_request
    rv = self.dispatch_request()
  File "/home/nate/.local/lib/python3.6/site-packages/flask/app.py", line 1799, in dispatch_request
    return self.view_functions[rule.endpoint](**req.view_args)
  File "/home/nate/.local/lib/python3.6/site-packages/flask_login/utils.py", line 261, in decorated_view
    return func(*args, **kwargs)
  File "/home/nate/Documents/BadDoggy/Artemis/app/routes.py", line 91, in explore
    if User.email in app.config.ADMINS:
AttributeError: 'Config' object has no attribute 'ADMINS'
2018-10-31 09:40:25,239 INFO: Artemis Startup [in /home/nate/Documents/BadDoggy/Artemis/app/__init__.py:50]
2018-10-31 09:40:27,480 ERROR: Exception on /explore [GET] [in /home/nate/.local/lib/python3.6/site-packages/flask/app.py:1761]
Traceback (most recent call last):
  File "/home/nate/.local/lib/python3.6/site-packages/flask/app.py", line 2292, in wsgi_app
    response = self.full_dispatch_request()
  File "/home/nate/.local/lib/python3.6/site-packages/flask/app.py", line 1815, in full_dispatch_request
    rv = self.handle_user_exception(e)
  File "/home/nate/.local/lib/python3.6/site-packages/flask/app.py", line 1718, in handle_user_exception
    reraise(exc_type, exc_value, tb)
  File "/home/nate/.local/lib/python3.6/site-packages/flask/_compat.py", line 35, in reraise
    raise value
  File "/home/nate/.local/lib/python3.6/site-packages/flask/app.py", line 1813, in full_dispatch_request
    rv = self.dispatch_request()
  File "/home/nate/.local/lib/python3.6/site-packages/flask/app.py", line 1799, in dispatch_request
    return self.view_functions[rule.endpoint](**req.view_args)
  File "/home/nate/.local/lib/python3.6/site-packages/flask_login/utils.py", line 261, in decorated_view
    return func(*args, **kwargs)
  File "/home/nate/Documents/BadDoggy/Artemis/app/routes.py", line 91, in explore
    if User.email in app.config.ADMINS:
AttributeError: 'Config' object has no attribute 'ADMINS'
2018-10-31 11:28:07,423 INFO: Artemis Startup [in /home/nate/Documents/BadDoggy/Artemis/app/__init__.py:50]
2019-01-03 10:20:34,257 INFO: Artemis Startup [in /home/nate/Documents/BadDoggy/Artemis/app/__init__.py:50]
2019-01-03 10:22:50,326 ERROR: Exception on /register [POST] [in /home/nate/.local/lib/python3.6/site-packages/flask/app.py:1761]
Traceback (most recent call last):
  File "/home/nate/.local/lib/python3.6/site-packages/flask/app.py", line 2292, in wsgi_app
    response = self.full_dispatch_request()
  File "/home/nate/.local/lib/python3.6/site-packages/flask/app.py", line 1815, in full_dispatch_request
    rv = self.handle_user_exception(e)
  File "/home/nate/.local/lib/python3.6/site-packages/flask/app.py", line 1718, in handle_user_exception
    reraise(exc_type, exc_value, tb)
  File "/home/nate/.local/lib/python3.6/site-packages/flask/_compat.py", line 35, in reraise
    raise value
  File "/home/nate/.local/lib/python3.6/site-packages/flask/app.py", line 1813, in full_dispatch_request
    rv = self.dispatch_request()
  File "/home/nate/.local/lib/python3.6/site-packages/flask/app.py", line 1799, in dispatch_request
    return self.view_functions[rule.endpoint](**req.view_args)
  File "/home/nate/Documents/BadDoggy/Artemis/app/routes.py", line 79, in register
    user = User(username=form.username.data, email=form.email.data, location=form.location.data)
  File "<string>", line 4, in __init__
  File "/home/nate/.local/lib/python3.6/site-packages/sqlalchemy/orm/state.py", line 424, in _initialize_instance
    manager.dispatch.init_failure(self, args, kwargs)
  File "/home/nate/.local/lib/python3.6/site-packages/sqlalchemy/util/langhelpers.py", line 66, in __exit__
    compat.reraise(exc_type, exc_value, exc_tb)
  File "/home/nate/.local/lib/python3.6/site-packages/sqlalchemy/util/compat.py", line 249, in reraise
    raise value
  File "/home/nate/.local/lib/python3.6/site-packages/sqlalchemy/orm/state.py", line 421, in _initialize_instance
    return manager.original_init(*mixed[1:], **kwargs)
  File "/home/nate/.local/lib/python3.6/site-packages/sqlalchemy/ext/declarative/base.py", line 746, in _declarative_constructor
    (k, cls_.__name__))
TypeError: 'location' is an invalid keyword argument for User
